Traceback (most recent call last):
  File "/Users/mbobra/anaconda/envs/helioml/lib/python3.8/site-packages/jupyter_cache/executors/utils.py", line 51, in single_nb_execution
    executenb(
  File "/Users/mbobra/anaconda/envs/helioml/lib/python3.8/site-packages/nbclient/client.py", line 1082, in execute
    return NotebookClient(nb=nb, resources=resources, km=km, **kwargs).execute()
  File "/Users/mbobra/anaconda/envs/helioml/lib/python3.8/site-packages/nbclient/util.py", line 74, in wrapped
    return just_run(coro(*args, **kwargs))
  File "/Users/mbobra/anaconda/envs/helioml/lib/python3.8/site-packages/nbclient/util.py", line 53, in just_run
    return loop.run_until_complete(coro)
  File "/Users/mbobra/anaconda/envs/helioml/lib/python3.8/asyncio/base_events.py", line 616, in run_until_complete
    return future.result()
  File "/Users/mbobra/anaconda/envs/helioml/lib/python3.8/site-packages/nbclient/client.py", line 535, in async_execute
    await self.async_execute_cell(
  File "/Users/mbobra/anaconda/envs/helioml/lib/python3.8/site-packages/nbclient/client.py", line 827, in async_execute_cell
    self._check_raise_for_error(cell, exec_reply)
  File "/Users/mbobra/anaconda/envs/helioml/lib/python3.8/site-packages/nbclient/client.py", line 735, in _check_raise_for_error
    raise CellExecutionError.from_cell_and_msg(cell, exec_reply['content'])
nbclient.exceptions.CellExecutionError: An error occurred while executing the following cell:
------------------
import os                       # manage filepaths
import requests                 # download the data
from zipfile import ZipFile     # unzips the data

r = requests.get('https://osf.io/zf32y/download', allow_redirects=True)
with open('example.zip', 'wb') as f:
    f.write(r.content)

with ZipFile('example.zip', 'r') as zfile:
   zfile.extractall()

# rename the folder to 'data'
os.rename('example', 'data')

for f in os.listdir('data'):
    print(f)
------------------

[0;31m---------------------------------------------------------------------------[0m
[0;31mOSError[0m                                   Traceback (most recent call last)
[0;32m<ipython-input-2-868b68369f86>[0m in [0;36m<module>[0;34m[0m
[1;32m     11[0m [0;34m[0m[0m
[1;32m     12[0m [0;31m# rename the folder to 'data'[0m[0;34m[0m[0;34m[0m[0;34m[0m[0m
[0;32m---> 13[0;31m [0mos[0m[0;34m.[0m[0mrename[0m[0;34m([0m[0;34m'example'[0m[0;34m,[0m [0;34m'data'[0m[0;34m)[0m[0;34m[0m[0;34m[0m[0m
[0m[1;32m     14[0m [0;34m[0m[0m
[1;32m     15[0m [0;32mfor[0m [0mf[0m [0;32min[0m [0mos[0m[0;34m.[0m[0mlistdir[0m[0;34m([0m[0;34m'data'[0m[0;34m)[0m[0;34m:[0m[0;34m[0m[0;34m[0m[0m

[0;31mOSError[0m: [Errno 66] Directory not empty: 'example' -> 'data'
OSError: [Errno 66] Directory not empty: 'example' -> 'data'

